Workbook

Sheet Start Here
B1: 4-Week Cash Flow Preview (Free Demo)
B2: FREE DEMO by LaneLedger Co. · Microsoft Excel and Google Sheets
B4: See your cash balance for the next 4 weeks, with recurring bills, open invoices and supplier bills placed in the right week.
B6: What this free demo includes
B7: • 4-week forecast: cash in, cash out by category, ending cash, credit line draws and status flags
B8: • Recurring engine: weekly, every 2 weeks, monthly, quarterly and yearly items placed automatically (12 rows)
B9: • Receivables with late-payer delays, Payables and One-off Items (a few rows each)
B10: • Settings with Best / Base / Worst scenarios
B12: The full version adds
B13: • The full 13-week horizon with totals and actual vs. forecast
B14: • Dashboard: lowest cash point, weeks below buffer, credit needed, runway, two charts and a plain-English action plan
B15: • Up to 60 rows on every input tab
... B22: This demo is free to use in your own business. Please don't resell it.

Sheet Forecast
A1: 4-Week Forecast (Free Demo)
A2: Weekly cash in, cash out and ending balance. Updates from every input tab. | G2: Free demo · Get the full 13-week forecast on Etsy →
B4: Week | C4: Week 1 | D4: Week 2 | E4: Week 3 | F4: Week 4
B5: Week starts | C5: =Settings!$B$6 -> 46328 | D5: =C5+7 -> 46335 | E5: =D5+7 -> 46342 | F5: =E5+7 -> 46349
B6: Week ends | C6: =C5+6 -> 46334 | D6: =D5+6 -> 46341 | E6: =E5+6 -> 46348 | F6: =F5+6 -> 46355
B8: Opening cash | C8: =Settings!$B$7 -> 42000 | D8: =C31 -> 36450 | E8: =D31 -> 30800 | F8: =E31 -> 23520 | H8: Weeks 5-13, totals and the Dashboard
B9: Cash in | H9: are in the full version →
B10: Customer collections (receivables) | C10: =SUMIFS(Receivables!$C$5:$C$64,Receivables!$G$5:$G$64,"Open",Receivables!$F$5:$F$64,">="&C$5,Receivables!$F$5:$F$64,"<="&C$6)+SUMIFS(Receivables!$C$5:$C$64,Receivables!$G$5:$G$64,"Open",Receivables!$F$5:$F$64,"<"&C$5) -> 14500 | D10: =SUMIFS(Receivables!$C$5:$C$64,Receivables!$G$5:$G$64,"Open",Receivables!$F$5:$F$64,">="&D$5,Receivables!$F$5:$F$64,"<="&D$6) -> 0 | E10: =SUMIFS(Receivables!$C$5:$C$64,Receivables!$G$5:$G$64,"Open",Receivables!$F$5:$F$64,">="&E$5,Receivables!$F$5:$F$64,"<="&E$6) -> 9800 | F10: =SUMIFS(Receivables!$C$5:$C$64,Receivables!$G$5:$G$64,"Open",Receivables!$F$5:$F$64,">="&F$5,Receivables!$F$5:$F$64,"<="&F$6) -> 0
B11: Recurring income | C11: =SUMIFS(Recurring!I$5:I$64,Recurring!$C$5:$C$64,"Inflow")*Settings!$E$22 -> 2800 | D11: =SUMIFS(Recurring!J$5:J$64,Recurring!$C$5:$C$64,"Inflow")*Settings!$E$22 -> 11300 | E11: =SUMIFS(Recurring!K$5:K$64,Recurring!$C$5:$C$64,"Inflow")*Settings!$E$22 -> 2800 | F11: =SUMIFS(Recurring!L$5:L$64,Recurring!$C$5:$C$64,"Inflow")*Settings!$E$22 -> 2800
B12: Other inflows (one-off) | C12: =SUMIFS('One-off Items'!$D$5:$D$64,'One-off Items'!$C$5:$C$64,"Inflow",'One-off Items'!$A$5:$A$64,">="&C$5,'One-off Items'!$A$5:$A$64,"<="&C$6) -> 0 | D12: =SUMIFS('One-off Items'!$D$5:$D$64,'One-off Items'!$C$5:$C$64,"Inflow",'One-off Items'!$A$5:$A$64,">="&D$5,'One-off Items'!$A$5:$A$64,"<="&D$6) -> 0 | E12: =SUMIFS('One-off Items'!$D$5:$D$64,'One-off Items'!$C$5:$C$64,"Inflow",'One-off Items'!$A$5:$A$64,">="&E$5,'One-off Items'!$A$5:$A$64,"<="&E$6) -> 0 | F12: =SUMIFS('One-off Items'!$D$5:$D$64,'One-off Items'!$C$5:$C$64,"Inflow",'One-off Items'!$A$5:$A$64,">="&F$5,'One-off Items'!$A$5:$A$64,"<="&F$6) -> 0
B13: Total cash in | C13: =SUM(C10:C12) -> 17300 | D13: =SUM(D10:D12) -> 11300 | E13: =SUM(E10:E12) -> 12600 | F13: =SUM(F10:F12) -> 2800
B14: Cash out
B15: Payroll | C15: =SUMIFS(Recurring!I$5:I$64,Recurring!$C$5:$C$64,"Outflow",Recurring!$B$5:$B$64,$B15)*Settings!$E$24 -> 18500 | D15: =SUMIFS(Recurring!J$5:J$64,Recurring!$C$5:$C$64,"Outflow",Recurring!$B$5:$B$64,$B15)*Settings!$E$24 -> 6000 | E15: =SUMIFS(Recurring!K$5:K$64,Recurring!$C$5:$C$64,"Outflow",Recurring!$B$5:$B$64,$B15)*Settings!$E$24 -> 18500 | F15: =SUMIFS(Recurring!L$5:L$64,Recurring!$C$5:$C$64,"Outflow",Recurring!$B$5:$B$64,$B15)*Settings!$E$24 -> 0
B16: Rent & Utilities | C16: =SUMIFS(Recurring!I$5:I$64,Recurring!$C$5:$C$64,"Outflow",Recurring!$B$5:$B$64,$B16)*Settings!$E$24 -> 0 | D16: =SUMIFS(Recurring!J$5:J$64,Recurring!$C$5:$C$64,"Outflow",Recurring!$B$5:$B$64,$B16)*Settings!$E$24 -> 650 | E16: =SUMIFS(Recurring!K$5:K$64,Recurring!$C$5:$C$64,"Outflow",Recurring!$B$5:$B$64,$B16)*Settings!$E$24 -> 0 | F16: =SUMIFS(Recurring!L$5:L$64,Recurring!$C$5:$C$64,"Outflow",Recurring!$B$5:$B$64,$B16)*Settings!$E$24 -> 0
B17: Software & Subscriptions | C17: =SUMIFS(Recurring!I$5:I$64,Recurring!$C$5:$C$64,"Outflow",Recurring!$B$5:$B$64,$B17)*Settings!$E$24 -> 1150 | D17: =SUMIFS(Recurring!J$5:J$64,Recurring!$C$5:$C$64,"Outflow",Recurring!$B$5:$B$64,$B17)*Settings!$E$24 -> 0 | E17: =SUMIFS(Recurring!K$5:K$64,Recurring!$C$5:$C$64,"Outflow",Recurring!$B$5:$B$64,$B17)*Settings!$E$24 -> 0 | F17: =SUMIFS(Recurring!L$5:L$64,Recurring!$C$5:$C$64,"Outflow",Recurring!$B$5:$B$64,$B17)*Settings!$E$24 -> 0
B18: Marketing | C18: =SUMIFS(Recurring!I$5:I$64,Recurring!$C$5:$C$64,"Outflow",Recurring!$B$5:$B$64,$B18)*Settings!$E$24 -> 0 | D18: =SUMIFS(Recurring!J$5:J$64,Recurring!$C$5:$C$64,"Outflow",Recurring!$B$5:$B$64,$B18)*Settings!$E$24 -> 2500 | E18: =SUMIFS(Recurring!K$5:K$64,Recurring!$C$5:$C$64,"Outflow",Recurring!$B$5:$B$64,$B18)*Settings!$E$24 -> 0 | F18: =SUMIFS(Recurring!L$5:L$64,Recurring!$C$5:$C$64,"Outflow",Recurring!$B$5:$B$64,$B18)*Settings!$E$24 -> 0
B19: Loan Payments | C19: =SUMIFS(Recurring!I$5:I$64,Recurring!$C$5:$C$64,"Outflow",Recurring!$B$5:$B$64,$B19)*Settings!$E$24 -> 0 | D19: =SUMIFS(Recurring!J$5:J$64,Recurring!$C$5:$C$64,"Outflow",Recurring!$B$5:$B$64,$B19)*Settings!$E$24 -> 0 | E19: =SUMIFS(Recurring!K$5:K$64,Recurring!$C$5:$C$64,"Outflow",Recurring!$B$5:$B$64,$B19)*Settings!$E$24 -> 1380 | F19: =SUMIFS(Recurring!L$5:L$64,Recurring!$C$5:$C$64,"Outflow",Recurring!$B$5:$B$64,$B19)*Settings!$E$24 -> 0
B20: Taxes | C20: =SUMIFS(Recurring!I$5:I$64,Recurring!$C$5:$C$64,"Outflow",Recurring!$B$5:$B$64,$B20)*Settings!$E$24 -> 0 | D20: =SUMIFS(Recurring!J$5:J$64,Recurring!$C$5:$C$64,"Outflow",Recurring!$B$5:$B$64,$B20)*Settings!$E$24 -> 0 | E20: =SUMIFS(Recurring!K$5:K$64,Recurring!$C$5:$C$64,"Outflow",Recurring!$B$5:$B$64,$B20)*Settings!$E$24 -> 0 | F20: =SUMIFS(Recurring!L$5:L$64,Recurring!$C$5:$C$64,"Outflow",Recurring!$B$5:$B$64,$B20)*Settings!$E$24 -> 0
B21: Other Expenses | C21: =SUMIFS(Recurring!I$5:I$64,Recurring!$C$5:$C$64,"Outflow",Recurring!$B$5:$B$64,$B21)*Settings!$E$24 -> 0 | D21: =SUMIFS(Recurring!J$5:J$64,Recurring!$C$5:$C$64,"Outflow",Recurring!$B$5:$B$64,$B21)*Settings!$E$24 -> 0 | E21: =SUMIFS(Recurring!K$5:K$64,Recurring!$C$5:$C$64,"Outflow",Recurring!$B$5:$B$64,$B21)*Settings!$E$24 -> 0 | F21: =SUMIFS(Recurring!L$5:L$64,Recurring!$C$5:$C$64,"Outflow",Recurring!$B$5:$B$64,$B21)*Settings!$E$24 -> 0
B22: Other recurring outflows | C22: =SUMIFS(Recurring!I$5:I$64,Recurring!$C$5:$C$64,"Outflow")*Settings!$E$24-SUM(C15:C21) -> 0 | D22: =SUMIFS(Recurring!J$5:J$64,Recurring!$C$5:$C$64,"Outflow")*Settings!$E$24-SUM(D15:D21) -> 0 | E22: =SUMIFS(Recurring!K$5:K$64,Recurring!$C$5:$C$64,"Outflow")*Settings!$E$24-SUM(E15:E21) -> 0 | F22: =SUMIFS(Recurring!L$5:L$64,Recurring!$C$5:$C$64,"Outflow")*Settings!$E$24-SUM(F15:F21) -> 0
B23: Supplier bills (payables) | C23: =SUMIFS(Payables!$C$5:$C$64,Payables!$E$5:$E$64,"Unpaid",Payables!$D$5:$D$64,">="&C$5,Payables!$D$5:$D$64,"<="&C$6)+SUMIFS(Payables!$C$5:$C$64,Payables!$E$5:$E$64,"Unpaid",Payables!$D$5:$D$64,"<"&C$5) -> 3200 | D23: =SUMIFS(Payables!$C$5:$C$64,Payables!$E$5:$E$64,"Unpaid",Payables!$D$5:$D$64,">="&D$5,Payables!$D$5:$D$64,"<="&D$6) -> 7800 | E23: =SUMIFS(Payables!$C$5:$C$64,Payables!$E$5:$E$64,"Unpaid",Payables!$D$5:$D$64,">="&E$5,Payables!$D$5:$D$64,"<="&E$6) -> 0 | F23: =SUMIFS(Payables!$C$5:$C$64,Payables!$E$5:$E$64,"Unpaid",Payables!$D$5:$D$64,">="&F$5,Payables!$D$5:$D$64,"<="&F$6) -> 2450
B24: Other outflows (one-off) | C24: =SUMIFS('One-off Items'!$D$5:$D$64,'One-off Items'!$C$5:$C$64,"Outflow",'One-off Items'!$A$5:$A$64,">="&C$5,'One-off Items'!$A$5:$A$64,"<="&C$6) -> 0 | D24: =SUMIFS('One-off Items'!$D$5:$D$64,'One-off Items'!$C$5:$C$64,"Outflow",'One-off Items'!$A$5:$A$64,">="&D$5,'One-off Items'!$A$5:$A$64,"<="&D$6) -> 0 | E24: =SUMIFS('One-off Items'!$D$5:$D$64,'One-off Items'!$C$5:$C$64,"Outflow",'One-off Items'!$A$5:$A$64,">="&E$5,'One-off Items'!$A$5:$A$64,"<="&E$6) -> 0 | F24: =SUMIFS('One-off Items'!$D$5:$D$64,'One-off Items'!$C$5:$C$64,"Outflow",'One-off Items'!$A$5:$A$64,">="&F$5,'One-off Items'!$A$5:$A$64,"<="&F$6) -> 0
B25: Total cash out | C25: =SUM(C15:C24) -> 22850 | D25: =SUM(D15:D24) -> 16950 | E25: =SUM(E15:E24) -> 19880 | F25: =SUM(F15:F24) -> 2450
B27: Net cash flow | C27: =C13-C25 -> -5550 | D27: =D13-D25 -> -5650 | E27: =E13-E25 -> -7280 | F27: =F13-F25 -> 350
B28: Credit line interest (estimate) | C28: =Settings!$B$12*Settings!$B$13/52 -> 0 | D28: =C32*Settings!$B$13/52 -> 0 | E28: =D32*Settings!$B$13/52 -> 0 | F28: =E32*Settings!$B$13/52 -> 0
B29: Credit line draw | C29: =IF(Settings!$B$11<=0,0,IF((C8+C27-C28)<Settings!$B$8,MIN(Settings!$B$8-(C8+C27-C28),MAX(0,Settings!$B$11-Settings!$B$12)),0)) -> 0 | D29: =IF(Settings!$B$11<=0,0,IF((D8+D27-D28)<Settings!$B$8,MIN(Settings!$B$8-(D8+D27-D28),MAX(0,Settings!$B$11-C32)),0)) -> 0 | E29: =IF(Settings!$B$11<=0,0,IF((E8+E27-E28)<Settings!$B$8,MIN(Settings!$B$8-(E8+E27-E28),MAX(0,Settings!$B$11-D32)),0)) -> 0 | F29: =IF(Settings!$B$11<=0,0,IF((F8+F27-F28)<Settings!$B$8,MIN(Settings!$B$8-(F8+F27-F28),MAX(0,Settings!$B$11-E32)),0)) -> 0
B30: Credit line repayment | C30: =IF(AND(Settings!$B$12>0,(C8+C27-C28)>Settings!$B$8),MIN(Settings!$B$12,(C8+C27-C28)-Settings!$B$8),0) -> 0 | D30: =IF(AND(C32>0,(D8+D27-D28)>Settings!$B$8),MIN(C32,(D8+D27-D28)-Settings!$B$8),0) -> 0 | E30: =IF(AND(D32>0,(E8+E27-E28)>Settings!$B$8),MIN(D32,(E8+E27-E28)-Settings!$B$8),0) -> 0 | F30: =IF(AND(E32>0,(F8+F27-F28)>Settings!$B$8),MIN(E32,(F8+F27-F28)-Settings!$B$8),0) -> 0
B31: ENDING CASH | C31: =(C8+C27-C28)+C29-C30 -> 36450 | D31: =(D8+D27-D28)+D29-D30 -> 30800 | E31: =(E8+E27-E28)+E29-E30 -> 23520 | F31: =(F8+F27-F28)+F29-F30 -> 23870
B32: Credit line balance | C32: =Settings!$B$12+C29-C30 -> 0 | D32: =C32+D29-D30 -> 0 | E32: =D32+E29-E30 -> 0 | F32: =E32+F29-F30 -> 0
B33: Minimum cash buffer | C33: =Settings!$B$8 -> 15000 | D33: =Settings!$B$8 -> 15000 | E33: =Settings!$B$8 -> 15000 | F33: =Settings!$B$8 -> 15000
B34: Status | C34: =IF(C31<0,"✗ Negative",IF(C31<C33,"! Below buffer","✓ OK")) -> ✓ OK | D34: =IF(D31<0,"✗ Negative",IF(D31<D33,"! Below buffer","✓ OK")) -> ✓ OK | E34: =IF(E31<0,"✗ Negative",IF(E31<E33,"! Below buffer","✓ OK")) -> ✓ OK | F34: =IF(F31<0,"✗ Negative",IF(F31<F33,"! Below buffer","✓ OK")) -> ✓ OK
B36: Cash with no credit line (for runway) | C36: =Settings!$B$7+SUM($C$27:C27) -> 36450 | D36: =Settings!$B$7+SUM($C$27:D27) -> 30800 | E36: =Settings!$B$7+SUM($C$27:E27) -> 23520 | F36: =Settings!$B$7+SUM($C$27:F27) -> 23870
B38: Actual ending cash (enter each week)
B39: Difference: actual − forecast | C39: =IF(C38="","",C38-C31) | D39: =IF(D38="","",D38-D31) | E39: =IF(E38="","",E38-E31) | F39: =IF(F38="","",F38-F31)

Sheet Settings
A1: Settings
A2: Your starting point and assumptions. Every other tab reads from here.
A4: Business | F4: Categories
A5: Business name | B5: Example: Harbor Design Studio | F5: Payroll
A6: Forecast start date (Monday of week 1) | B6: 46328 | F6: Rent & Utilities
A7: Bank balance at the start date | B7: 42000 | F7: Software & Subscriptions
A8: Minimum cash buffer (never go below) | B8: 15000 | F8: Marketing
F9: Loan Payments
A10: Credit line (optional) | F10: Taxes
A11: Credit line limit (0 if none) | B11: 25000 | F11: Other Expenses
A12: Credit line balance at the start date | B12: 0 | F12: Sales & Retainers
A13: Credit line interest rate (yearly, estimate) | B13: 0.09 | F13: Other Income
A15: Collections | F15: Rows 5-11 are expense categories (shown
A16: Default days late for customer invoices | B16: 7 | F16: on the Forecast). Rows 12-13 are income.
A18: Scenario
A19: Active scenario | B19: Base
A21: Scenario assumptions | B21: Base | C21: Best | D21: Worst | E21: Active
A22: Recurring income multiplier | B22: 1 | C22: 1.1 | D22: 0.85 | E22: =INDEX(B22:D22,MATCH($B$19,$B$21:$D$21,0)) -> 1
A23: Extra collection delay (days) | B23: 0 | C23: 0 | D23: 14 | E23: =INDEX(B23:D23,MATCH($B$19,$B$21:$D$21,0)) -> 0
A24: Recurring expense multiplier | B24: 1 | C24: 0.97 | D24: 1.05 | E24: =INDEX(B24:D24,MATCH($B$19,$B$21:$D$21,0)) -> 1

Sheet Recurring
A1: Recurring Items
A2: Regular income and costs. Each item is placed in the right weeks automatically.
I3: Amount falling in each week (by week start date)
A4: Item | B4: Category | C4: Type | D4: Amount | E4: Frequency | F4: First date | G4: End date (optional) | I4: =Forecast!C5 -> 46328 | J4: =Forecast!D5 -> 46335 | K4: =Forecast!E5 -> 46342 | L4: =Forecast!F5 -> 46349
A5: Team payroll | B5: Payroll | C5: Outflow | D5: 18500 | E5: Every 2 weeks | F5: 46332 | I5: =IF(OR($A5="",$D5="",$E5="",$F5=""),0,IFERROR(MAX(0,IF(MIN((I$4+6),IF($G5="",(I$4+6),$G5))<$F5,0,CHOOSE(MATCH($E5,{"Weekly","Every 2 weeks","Monthly","Quarterly","Yearly","One-time"},0),INT((MIN((I$4+6),IF($G5="",(I$4+6),$G5))-$F5)/7)+1,INT((MIN((I$4+6),IF($G5="",(I$4+6),$G5))-$F5)/14)+1,((YEAR(MIN((I$4+6),IF($G5="",(I$4+6),$G5)))-YEAR($F5))*12+MONTH(MIN((I$4+6),IF($G5="",(I$4+6),$G5)))-MONTH($F5)-IF(DAY(MIN((I$4+6),IF($G5="",(I$4+6),$G5)))<DAY($F5),1,0))+1,INT(((YEAR(MIN((I$4+6),IF($G5="",(I$4+6),$G5)))-YEAR($F5))*12+MONTH(MIN((I$4+6),IF($G5="",(I$4+6),$G5)))-MONTH($F5)-IF(DAY(MIN((I$4+6),IF($G5="",(I$4+6),$G5)))<DAY($F5),1,0))/3)+1,INT(((YEAR(MIN((I$4+6),IF($G5="",(I$4+6),$G5)))-YEAR($F5))*12+MONTH(MIN((I$4+6),IF($G5="",(I$4+6),$G5)))-MONTH($F5)-IF(DAY(MIN((I$4+6),IF($G5="",(I$4+6),$G5)))<DAY($F5),1,0))/12)+1,1))-IF((I$4-1)<$F5,0,CHOOSE(MATCH($E5,{"Weekly","Every 2 weeks","Monthly","Quarterly","Yearly","One-time"},0),INT(((I$4-1)-$F5)/7)+1,INT(((I$4-1)-$F5)/14)+1,((YEAR((I$4-1))-YEAR($F5))*12+MONTH((I$4-1))-MONTH($F5)-IF(DAY((I$4-1))<DAY($F5),1,0))+1,INT(((YEAR((I$4-1))-YEAR($F5))*12+MONTH((I$4-1))-MONTH($F5)-IF(DAY((I$4-1))<DAY($F5),1,0))/3)+1,INT(((YEAR((I$4-1))-YEAR($F5))*12+MONTH((I$4-1))-MONTH($F5)-IF(DAY((I$4-1))<DAY($F5),1,0))/12)+1,1))),0)*$D5) -> 18500 | J5: =IF(OR($A5="",$D5="",$E5="",$F5=""),0,IFERROR(MAX(0,IF(MIN((J$4+6),IF($G5="",(J$4+6),$G5))<$F5,0,CHOOSE(MATCH($E5,{"Weekly","Every 2 weeks","Monthly","Quarterly","Yearly","One-time"},0),INT((MIN((J$4+6),IF($G5="",(J$4+6),$G5))-$F5)/7)+1,INT((MIN((J$4+6),IF($G5="",(J$4+6),$G5))-$F5)/14)+1,((YEAR(MIN((J$4+6),IF($G5="",(J$4+6),$G5)))-YEAR($F5))*12+MONTH(MIN((J$4+6),IF($G5="",(J$4+6),$G5)))-MONTH($F5)-IF(DAY(MIN((J$4+6),IF($G5="",(J$4+6),$G5)))<DAY($F5),1,0))+1,INT(((YEAR(MIN((J$4+6),IF($G5="",(J$4+6),$G5)))-YEAR($F5))*12+MONTH(MIN((J$4+6),IF($G5="",(J$4+6),$G5)))-MONTH($F5)-IF(DAY(MIN((J$4+6),IF($G5="",(J$4+6),$G5)))<DAY($F5),1,0))/3)+1,INT(((YEAR(MIN((J$4+6),IF($G5="",(J$4+6),$G5)))-YEAR($F5))*12+MONTH(MIN((J$4+6),IF($G5="",(J$4+6),$G5)))-MONTH($F5)-IF(DAY(MIN((J$4+6),IF($G5="",(J$4+6),$G5)))<DAY($F5),1,0))/12)+1,1))-IF((J$4-1)<$F5,0,CHOOSE(MATCH($E5,{"Weekly","Every 2 weeks","Monthly","Quarterly","Yearly","One-time"},0),INT(((J$4-1)-$F5)/7)+1,INT(((J$4-1)-$F5)/14)+1,((YEAR((J$4-1))-YEAR($F5))*12+MONTH((J$4-1))-MONTH($F5)-IF(DAY((J$4-1))<DAY($F5),1,0))+1,INT(((YEAR((J$4-1))-YEAR($F5))*12+MONTH((J$4-1))-MONTH($F5)-IF(DAY((J$4-1))<DAY($F5),1,0))/3)+1,INT(((YEAR((J$4-1))-YEAR($F5))*12+MONTH((J$4-1))-MONTH($F5)-IF(DAY((J$4-1))<DAY($F5),1,0))/12)+1,1))),0)*$D5) -> 0 | K5: =IF(OR($A5="",$D5="",$E5="",$F5=""),0,IFERROR(MAX(0,IF(MIN((K$4+6),IF($G5="",(K$4+6),$G5))<$F5,0,CHOOSE(MATCH($E5,{"Weekly","Every 2 weeks","Monthly","Quarterly","Yearly","One-time"},0),INT((MIN((K$4+6),IF($G5="",(K$4+6),$G5))-$F5)/7)+1,INT((MIN((K$4+6),IF($G5="",(K$4+6),$G5))-$F5)/14)+1,((YEAR(MIN((K$4+6),IF($G5="",(K$4+6),$G5)))-YEAR($F5))*12+MONTH(MIN((K$4+6),IF($G5="",(K$4+6),$G5)))-MONTH($F5)-IF(DAY(MIN((K$4+6),IF($G5="",(K$4+6),$G5)))<DAY($F5),1,0))+1,INT(((YEAR(MIN((K$4+6),IF($G5="",(K$4+6),$G5)))-YEAR($F5))*12+MONTH(MIN((K$4+6),IF($G5="",(K$4+6),$G5)))-MONTH($F5)-IF(DAY(MIN((K$4+6),IF($G5="",(K$4+6),$G5)))<DAY($F5),1,0))/3)+1,INT(((YEAR(MIN((K$4+6),IF($G5="",(K$4+6),$G5)))-YEAR($F5))*12+MONTH(MIN((K$4+6),IF($G5="",(K$4+6),$G5)))-MONTH($F5)-IF(DAY(MIN((K$4+6),IF($G5="",(K$4+6),$G5)))<DAY($F5),1,0))/12)+1,1))-IF((K$4-1)<$F5,0,CHOOSE(MATCH($E5,{"Weekly","Every 2 weeks","Monthly","Quarterly","Yearly","One-time"},0),INT(((K$4-1)-$F5)/7)+1,INT(((K$4-1)-$F5)/14)+1,((YEAR((K$4-1))-YEAR($F5))*12+MONTH((K$4-1))-MONTH($F5)-IF(DAY((K$4-1))<DAY($F5),1,0))+1,INT(((YEAR((K$4-1))-YEAR($F5))*12+MONTH((K$4-1))-MONTH($F5)-IF(DAY((K$4-1))<DAY($F5),1,0))/3)+1,INT(((YEAR((K$4-1))-YEAR($F5))*12+MONTH((K$4-1))-MONTH($F5)-IF(DAY((K$4-1))<DAY($F5),1,0))/12)+1,1))),0)*$D5) -> 18500 | L5: =IF(OR($A5="",$D5="",$E5="",$F5=""),0,IFERROR(MAX(0,IF(MIN((L$4+6),IF($G5="",(L$4+6),$G5))<$F5,0,CHOOSE(MATCH($E5,{"Weekly","Every 2 weeks","Monthly","Quarterly","Yearly","One-time"},0),INT((MIN((L$4+6),IF($G5="",(L$4+6),$G5))-$F5)/7)+1,INT((MIN((L$4+6),IF($G5="",(L$4+6),$G5))-$F5)/14)+1,((YEAR(MIN((L$4+6),IF($G5="",(L$4+6),$G5)))-YEAR($F5))*12+MONTH(MIN((L$4+6),IF($G5="",(L$4+6),$G5)))-MONTH($F5)-IF(DAY(MIN((L$4+6),IF($G5="",(L$4+6),$G5)))<DAY($F5),1,0))+1,INT(((YEAR(MIN((L$4+6),IF($G5="",(L$4+6),$G5)))-YEAR($F5))*12+MONTH(MIN((L$4+6),IF($G5="",(L$4+6),$G5)))-MONTH($F5)-IF(DAY(MIN((L$4+6),IF($G5="",(L$4+6),$G5)))<DAY($F5),1,0))/3)+1,INT(((YEAR(MIN((L$4+6),IF($G5="",(L$4+6),$G5)))-YEAR($F5))*12+MONTH(MIN((L$4+6),IF($G5="",(L$4+6),$G5)))-MONTH($F5)-IF(DAY(MIN((L$4+6),IF($G5="",(L$4+6),$G5)))<DAY($F5),1,0))/12)+1,1))-IF((L$4-1)<$F5,0,CHOOSE(MATCH($E5,{"Weekly","Every 2 weeks","Monthly","Quarterly","Yearly","One-time"},0),INT(((L$4-1)-$F5)/7)+1,INT(((L$4-1)-$F5)/14)+1,((YEAR((L$4-1))-YEAR($F5))*12+MONTH((L$4-1))-MONTH($F5)-IF(DAY((L$4-1))<DAY($F5),1,0))+1,INT(((YEAR((L$4-1))-YEAR($F5))*12+MONTH((L$4-1))-MONTH($F5)-IF(DAY((L$4-1))<DAY($F5),1,0))/3)+1,INT(((YEAR((L$4-1))-YEAR($F5))*12+MONTH((L$4-1))-MONTH($F5)-IF(DAY((L$4-1))<DAY($F5),1,0))/12)+1,1))),0)*$D5) -> 0
A6: Owner pay | B6: Payroll | C6: Outflow | D6: 6000 | E6: Monthly | F6: 46341 | I6: =IF(OR($A6="",$D6="",$E6="",$F6=""),0,IFERROR(MAX(0,IF(MIN((I$4+6),IF($G6="",(I$4+6),$G6))<$F6,0,CHOOSE(MATCH($E6,{"Weekly","Every 2 weeks","Monthly","Quarterly","Yearly","One-time"},0),INT((MIN((I$4+6),IF($G6="",(I$4+6),$G6))-$F6)/7)+1,INT((MIN((I$4+6),IF($G6="",(I$4+6),$G6))-$F6)/14)+1,((YEAR(MIN((I$4+6),IF($G6="",(I$4+6),$G6)))-YEAR($F6))*12+MONTH(MIN((I$4+6),IF($G6="",(I$4+6),$G6)))-MONTH($F6)-IF(DAY(MIN((I$4+6),IF($G6="",(I$4+6),$G6)))<DAY($F6),1,0))+1,INT(((YEAR(MIN((I$4+6),IF($G6="",(I$4+6),$G6)))-YEAR($F6))*12+MONTH(MIN((I$4+6),IF($G6="",(I$4+6),$G6)))-MONTH($F6)-IF(DAY(MIN((I$4+6),IF($G6="",(I$4+6),$G6)))<DAY($F6),1,0))/3)+1,INT(((YEAR(MIN((I$4+6),IF($G6="",(I$4+6),$G6)))-YEAR($F6))*12+MONTH(MIN((I$4+6),IF($G6="",(I$4+6),$G6)))-MONTH($F6)-IF(DAY(MIN((I$4+6),IF($G6="",(I$4+6),$G6)))<DAY($F6),1,0))/12)+1,1))-IF((I$4-1)<$F6,0,CHOOSE(MATCH($E6,{"Weekly","Every 2 weeks","Monthly","Quarterly","Yearly","One-time"},0),INT(((I$4-1)-$F6)/7)+1,INT(((I$4-1)-$F6)/14)+1,((YEAR((I$4-1))-YEAR($F6))*12+MONTH((I$4-1))-MONTH($F6)-IF(DAY((I$4-1))<DAY($F6),1,0))+1,INT(((YEAR((I$4-1))-YEAR($F6))*12+MONTH((I$4-1))-MONTH($F6)-IF(DAY((I$4-1))<DAY($F6),1,0))/3)+1,INT(((YEAR((I$4-1))-YEAR($F6))*12+MONTH((I$4-1))-MONTH($F6)-IF(DAY((I$4-1))<DAY($F6),1,0))/12)+1,1))),0)*$D6) -> 0 | J6: =IF(OR($A6="",$D6="",$E6="",$F6=""),0,IFERROR(MAX(0,IF(MIN((J$4+6),IF($G6="",(J$4+6),$G6))<$F6,0,CHOOSE(MATCH($E6,{"Weekly","Every 2 weeks","Monthly","Quarterly","Yearly","One-time"},0),INT((MIN((J$4+6),IF($G6="",(J$4+6),$G6))-$F6)/7)+1,INT((MIN((J$4+6),IF($G6="",(J$4+6),$G6))-$F6)/14)+1,((YEAR(MIN((J$4+6),IF($G6="",(J$4+6),$G6)))-YEAR($F6))*12+MONTH(MIN((J$4+6),IF($G6="",(J$4+6),$G6)))-MONTH($F6)-IF(DAY(MIN((J$4+6),IF($G6="",(J$4+6),$G6)))<DAY($F6),1,0))+1,INT(((YEAR(MIN((J$4+6),IF($G6="",(J$4+6),$G6)))-YEAR($F6))*12+MONTH(MIN((J$4+6),IF($G6="",(J$4+6),$G6)))-MONTH($F6)-IF(DAY(MIN((J$4+6),IF($G6="",(J$4+6),$G6)))<DAY($F6),1,0))/3)+1,INT(((YEAR(MIN((J$4+6),IF($G6="",(J$4+6),$G6)))-YEAR($F6))*12+MONTH(MIN((J$4+6),IF($G6="",(J$4+6),$G6)))-MONTH($F6)-IF(DAY(MIN((J$4+6),IF($G6="",(J$4+6),$G6)))<DAY($F6),1,0))/12)+1,1))-IF((J$4-1)<$F6,0,CHOOSE(MATCH($E6,{"Weekly","Every 2 weeks","Monthly","Quarterly","Yearly","One-time"},0),INT(((J$4-1)-$F6)/7)+1,INT(((J$4-1)-$F6)/14)+1,((YEAR((J$4-1))-YEAR($F6))*12+MONTH((J$4-1))-MONTH($F6)-IF(DAY((J$4-1))<DAY($F6),1,0))+1,INT(((YEAR((J$4-1))-YEAR($F6))*12+MONTH((J$4-1))-MONTH($F6)-IF(DAY((J$4-1))<DAY($F6),1,0))/3)+1,INT(((YEAR((J$4-1))-YEAR($F6))*12+MONTH((J$4-1))-MONTH($F6)-IF(DAY((J$4-1))<DAY($F6),1,0))/12)+1,1))),0)*$D6) -> 6000 | K6: =IF(OR($A6="",$D6="",$E6="",$F6=""),0,IFERROR(MAX(0,IF(MIN((K$4+6),IF($G6="",(K$4+6),$G6))<$F6,0,CHOOSE(MATCH($E6,{"Weekly","Every 2 weeks","Monthly","Quarterly","Yearly","One-time"},0),INT((MIN((K$4+6),IF($G6="",(K$4+6),$G6))-$F6)/7)+1,INT((MIN((K$4+6),IF($G6="",(K$4+6),$G6))-$F6)/14)+1,((YEAR(MIN((K$4+6),IF($G6="",(K$4+6),$G6)))-YEAR($F6))*12+MONTH(MIN((K$4+6),IF($G6="",(K$4+6),$G6)))-MONTH($F6)-IF(DAY(MIN((K$4+6),IF($G6="",(K$4+6),$G6)))<DAY($F6),1,0))+1,INT(((YEAR(MIN((K$4+6),IF($G6="",(K$4+6),$G6)))-YEAR($F6))*12+MONTH(MIN((K$4+6),IF($G6="",(K$4+6),$G6)))-MONTH($F6)-IF(DAY(MIN((K$4+6),IF($G6="",(K$4+6),$G6)))<DAY($F6),1,0))/3)+1,INT(((YEAR(MIN((K$4+6),IF($G6="",(K$4+6),$G6)))-YEAR($F6))*12+MONTH(MIN((K$4+6),IF($G6="",(K$4+6),$G6)))-MONTH($F6)-IF(DAY(MIN((K$4+6),IF($G6="",(K$4+6),$G6)))<DAY($F6),1,0))/12)+1,1))-IF((K$4-1)<$F6,0,CHOOSE(MATCH($E6,{"Weekly","Every 2 weeks","Monthly","Quarterly","Yearly","One-time"},0),INT(((K$4-1)-$F6)/7)+1,INT(((K$4-1)-$F6)/14)+1,((YEAR((K$4-1))-YEAR($F6))*12+MONTH((K$4-1))-MONTH($F6)-IF(DAY((K$4-1))<DAY($F6),1,0))+1,INT(((YEAR((K$4-1))-YEAR($F6))*12+MONTH((K$4-1))-MONTH($F6)-IF(DAY((K$4-1))<DAY($F6),1,0))/3)+1,INT(((YEAR((K$4-1))-YEAR($F6))*12+MONTH((K$4-1))-MONTH($F6)-IF(DAY((K$4-1))<DAY($F6),1,0))/12)+1,1))),0)*$D6) -> 0 | L6: =IF(OR($A6="",$D6="",$E6="",$F6=""),0,IFERROR(MAX(0,IF(MIN((L$4+6),IF($G6="",(L$4+6),$G6))<$F6,0,CHOOSE(MATCH($E6,{"Weekly","Every 2 weeks","Monthly","Quarterly","Yearly","One-time"},0),INT((MIN((L$4+6),IF($G6="",(L$4+6),$G6))-$F6)/7)+1,INT((MIN((L$4+6),IF($G6="",(L$4+6),$G6))-$F6)/14)+1,((YEAR(MIN((L$4+6),IF($G6="",(L$4+6),$G6)))-YEAR($F6))*12+MONTH(MIN((L$4+6),IF($G6="",(L$4+6),$G6)))-MONTH($F6)-IF(DAY(MIN((L$4+6),IF($G6="",(L$4+6),$G6)))<DAY($F6),1,0))+1,INT(((YEAR(MIN((L$4+6),IF($G6="",(L$4+6),$G6)))-YEAR($F6))*12+MONTH(MIN((L$4+6),IF($G6="",(L$4+6),$G6)))-MONTH($F6)-IF(DAY(MIN((L$4+6),IF($G6="",(L$4+6),$G6)))<DAY($F6),1,0))/3)+1,INT(((YEAR(MIN((L$4+6),IF($G6="",(L$4+6),$G6)))-YEAR($F6))*12+MONTH(MIN((L$4+6),IF($G6="",(L$4+6),$G6)))-MONTH($F6)-IF(DAY(MIN((L$4+6),IF($G6="",(L$4+6),$G6)))<DAY($F6),1,0))/12)+1,1))-IF((L$4-1)<$F6,0,CHOOSE(MATCH($E6,{"Weekly","Every 2 weeks","Monthly","Quarterly","Yearly","One-time"},0),INT(((L$4-1)-$F6)/7)+1,INT(((L$4-1)-$F6)/14)+1,((YEAR((L$4-1))-YEAR($F6))*12+MONTH((L$4-1))-MONTH($F6)-IF(DAY((L$4-1))<DAY($F6),1,0))+1,INT(((YEAR((L$4-1))-YEAR($F6))*12+MONTH((L$4-1))-MONTH($F6)-IF(DAY((L$4-1))<DAY($F6),1,0))/3)+1,INT(((YEAR((L$4-1))-YEAR($F6))*12+MONTH((L$4-1))-MONTH($F6)-IF(DAY((L$4-1))<DAY($F6),1,0))/12)+1,1))),0)*$D6) -> 0
A7: Office rent | B7: Rent & Utilities | C7: Outflow | D7: 4200 | E7: Monthly | F7: 46327 | I7: =IF(OR($A7="",$D7="",$E7="",$F7=""),0,IFERROR(MAX(0,IF(MIN((I$4+6),IF($G7="",(I$4+6),$G7))<$F7,0,CHOOSE(MATCH($E7,{"Weekly","Every 2 weeks","Monthly","Quarterly","Yearly","One-time"},0),INT((MIN((I$4+6),IF($G7="",(I$4+6),$G7))-$F7)/7)+1,INT((MIN((I$4+6),IF($G7="",(I$4+6),$G7))-$F7)/14)+1,((YEAR(MIN((I$4+6),IF($G7="",(I$4+6),$G7)))-YEAR($F7))*12+MONTH(MIN((I$4+6),IF($G7="",(I$4+6),$G7)))-MONTH($F7)-IF(DAY(MIN((I$4+6),IF($G7="",(I$4+6),$G7)))<DAY($F7),1,0))+1,INT(((YEAR(MIN((I$4+6),IF($G7="",(I$4+6),$G7)))-YEAR($F7))*12+MONTH(MIN((I$4+6),IF($G7="",(I$4+6),$G7)))-MONTH($F7)-IF(DAY(MIN((I$4+6),IF($G7="",(I$4+6),$G7)))<DAY($F7),1,0))/3)+1,INT(((YEAR(MIN((I$4+6),IF($G7="",(I$4+6),$G7)))-YEAR($F7))*12+MONTH(MIN((I$4+6),IF($G7="",(I$4+6),$G7)))-MONTH($F7)-IF(DAY(MIN((I$4+6),IF($G7="",(I$4+6),$G7)))<DAY($F7),1,0))/12)+1,1))-IF((I$4-1)<$F7,0,CHOOSE(MATCH($E7,{"Weekly","Every 2 weeks","Monthly","Quarterly","Yearly","One-time"},0),INT(((I$4-1)-$F7)/7)+1,INT(((I$4-1)-$F7)/14)+1,((YEAR((I$4-1))-YEAR($F7))*12+MONTH((I$4-1))-MONTH($F7)-IF(DAY((I$4-1))<DAY($F7),1,0))+1,INT(((YEAR((I$4-1))-YEAR($F7))*12+MONTH((I$4-1))-MONTH($F7)-IF(DAY((I$4-1))<DAY($F7),1,0))/3)+1,INT(((YEAR((I$4-1))-YEAR($F7))*12+MONTH((I$4-1))-MONTH($F7)-IF(DAY((I$4-1))<DAY($F7),1,0))/12)+1,1))),0)*$D7) -> 0 | J7: =IF(OR($A7="",$D7="",$E7="",$F7=""),0,IFERROR(MAX(0,IF(MIN((J$4+6),IF($G7="",(J$4+6),$G7))<$F7,0,CHOOSE(MATCH($E7,{"Weekly","Every 2 weeks","Monthly","Quarterly","Yearly","One-time"},0),INT((MIN((J$4+6),IF($G7="",(J$4+6),$G7))-$F7)/7)+1,INT((MIN((J$4+6),IF($G7="",(J$4+6),$G7))-$F7)/14)+1,((YEAR(MIN((J$4+6),IF($G7="",(J$4+6),$G7)))-YEAR($F7))*12+MONTH(MIN((J$4+6),IF($G7="",(J$4+6),$G7)))-MONTH($F7)-IF(DAY(MIN((J$4+6),IF($G7="",(J$4+6),$G7)))<DAY($F7),1,0))+1,INT(((YEAR(MIN((J$4+6),IF($G7="",(J$4+6),$G7)))-YEAR($F7))*12+MONTH(MIN((J$4+6),IF($G7="",(J$4+6),$G7)))-MONTH($F7)-IF(DAY(MIN((J$4+6),IF($G7="",(J$4+6),$G7)))<DAY($F7),1,0))/3)+1,INT(((YEAR(MIN((J$4+6),IF($G7="",(J$4+6),$G7)))-YEAR($F7))*12+MONTH(MIN((J$4+6),IF($G7="",(J$4+6),$G7)))-MONTH($F7)-IF(DAY(MIN((J$4+6),IF($G7="",(J$4+6),$G7)))<DAY($F7),1,0))/12)+1,1))-IF((J$4-1)<$F7,0,CHOOSE(MATCH($E7,{"Weekly","Every 2 weeks","Monthly","Quarterly","Yearly","One-time"},0),INT(((J$4-1)-$F7)/7)+1,INT(((J$4-1)-$F7)/14)+1,((YEAR((J$4-1))-YEAR($F7))*12+MONTH((J$4-1))-MONTH($F7)-IF(DAY((J$4-1))<DAY($F7),1,0))+1,INT(((YEAR((J$4-1))-YEAR($F7))*12+MONTH((J$4-1))-MONTH($F7)-IF(DAY((J$4-1))<DAY($F7),1,0))/3)+1,INT(((YEAR((J$4-1))-YEAR($F7))*12+MONTH((J$4-1))-MONTH($F7)-IF(DAY((J$4-1))<DAY($F7),1,0))/12)+1,1))),0)*$D7) -> 0 | K7: =IF(OR($A7="",$D7="",$E7="",$F7=""),0,IFERROR(MAX(0,IF(MIN((K$4+6),IF($G7="",(K$4+6),$G7))<$F7,0,CHOOSE(MATCH($E7,{"Weekly","Every 2 weeks","Monthly","Quarterly","Yearly","One-time"},0),INT((MIN((K$4+6),IF($G7="",(K$4+6),$G7))-$F7)/7)+1,INT((MIN((K$4+6),IF($G7="",(K$4+6),$G7))-$F7)/14)+1,((YEAR(MIN((K$4+6),IF($G7="",(K$4+6),$G7)))-YEAR($F7))*12+MONTH(MIN((K$4+6),IF($G7="",(K$4+6),$G7)))-MONTH($F7)-IF(DAY(MIN((K$4+6),IF($G7="",(K$4+6),$G7)))<DAY($F7),1,0))+1,INT(((YEAR(MIN((K$4+6),IF($G7="",(K$4+6),$G7)))-YEAR($F7))*12+MONTH(MIN((K$4+6),IF($G7="",(K$4+6),$G7)))-MONTH($F7)-IF(DAY(MIN((K$4+6),IF($G7="",(K$4+6),$G7)))<DAY($F7),1,0))/3)+1,INT(((YEAR(MIN((K$4+6),IF($G7="",(K$4+6),$G7)))-YEAR($F7))*12+MONTH(MIN((K$4+6),IF($G7="",(K$4+6),$G7)))-MONTH($F7)-IF(DAY(MIN((K$4+6),IF($G7="",(K$4+6),$G7)))<DAY($F7),1,0))/12)+1,1))-IF((K$4-1)<$F7,0,CHOOSE(MATCH($E7,{"Weekly","Every 2 weeks","Monthly","Quarterly","Yearly","One-time"},0),INT(((K$4-1)-$F7)/7)+1,INT(((K$4-1)-$F7)/14)+1,((YEAR((K$4-1))-YEAR($F7))*12+MONTH((K$4-1))-MONTH($F7)-IF(DAY((K$4-1))<DAY($F7),1,0))+1,INT(((YEAR((K$4-1))-YEAR($F7))*12+MONTH((K$4-1))-MONTH($F7)-IF(DAY((K$4-1))<DAY($F7),1,0))/3)+1,INT(((YEAR((K$4-1))-YEAR($F7))*12+MONTH((K$4-1))-MONTH($F7)-IF(DAY((K$4-1))<DAY($F7),1,0))/12)+1,1))),0)*$D7) -> 0 | L7: =IF(OR($A7="",$D7="",$E7="",$F7=""),0,IFERROR(MAX(0,IF(MIN((L$4+6),IF($G7="",(L$4+6),$G7))<$F7,0,CHOOSE(MATCH($E7,{"Weekly","Every 2 weeks","Monthly","Quarterly","Yearly","One-time"},0),INT((MIN((L$4+6),IF($G7="",(L$4+6),$G7))-$F7)/7)+1,INT((MIN((L$4+6),IF($G7="",(L$4+6),$G7))-$F7)/14)+1,((YEAR(MIN((L$4+6),IF($G7="",(L$4+6),$G7)))-YEAR($F7))*12+MONTH(MIN((L$4+6),IF($G7="",(L$4+6),$G7)))-MONTH($F7)-IF(DAY(MIN((L$4+6),IF($G7="",(L$4+6),$G7)))<DAY($F7),1,0))+1,INT(((YEAR(MIN((L$4+6),IF($G7="",(L$4+6),$G7)))-YEAR($F7))*12+MONTH(MIN((L$4+6),IF($G7="",(L$4+6),$G7)))-MONTH($F7)-IF(DAY(MIN((L$4+6),IF($G7="",(L$4+6),$G7)))<DAY($F7),1,0))/3)+1,INT(((YEAR(MIN((L$4+6),IF($G7="",(L$4+6),$G7)))-YEAR($F7))*12+MONTH(MIN((L$4+6),IF($G7="",(L$4+6),$G7)))-MONTH($F7)-IF(DAY(MIN((L$4+6),IF($G7="",(L$4+6),$G7)))<DAY($F7),1,0))/12)+1,1))-IF((L$4-1)<$F7,0,CHOOSE(MATCH($E7,{"Weekly","Every 2 weeks","Monthly","Quarterly","Yearly","One-time"},0),INT(((L$4-1)-$F7)/7)+1,INT(((L$4-1)-$F7)/14)+1,((YEAR((L$4-1))-YEAR($F7))*12+MONTH((L$4-1))-MONTH($F7)-IF(DAY((L$4-1))<DAY($F7),1,0))+1,INT(((YEAR((L$4-1))-YEAR($F7))*12+MONTH((L$4-1))-MONTH($F7)-IF(DAY((L$4-1))<DAY($F7),1,0))/3)+1,INT(((YEAR((L$4-1))-YEAR($F7))*12+MONTH((L$4-1))-MONTH($F7)-IF(DAY((L$4-1))<DAY($F7),1,0))/12)+1,1))),0)*$D7) -> 0
A8: Utilities & internet | B8: Rent & Utilities | C8: Outflow | D8: 650 | E8: Monthly | F8: 46336 | I8: =IF(OR($A8="",$D8="",$E8="",$F8=""),0,IFERROR(MAX(0,IF(MIN((I$4+6),IF($G8="",(I$4+6),$G8))<$F8,0,CHOOSE(MATCH($E8,{"Weekly","Every 2 weeks","Monthly","Quarterly","Yearly","One-time"},0),INT((MIN((I$4+6),IF($G8="",(I$4+6),$G8))-$F8)/7)+1,INT((MIN((I$4+6),IF($G8="",(I$4+6),$G8))-$F8)/14)+1,((YEAR(MIN((I$4+6),IF($G8="",(I$4+6),$G8)))-YEAR($F8))*12+MONTH(MIN((I$4+6),IF($G8="",(I$4+6),$G8)))-MONTH($F8)-IF(DAY(MIN((I$4+6),IF($G8="",(I$4+6),$G8)))<DAY($F8),1,0))+1,INT(((YEAR(MIN((I$4+6),IF($G8="",(I$4+6),$G8)))-YEAR($F8))*12+MONTH(MIN((I$4+6),IF($G8="",(I$4+6),$G8)))-MONTH($F8)-IF(DAY(MIN((I$4+6),IF($G8="",(I$4+6),$G8)))<DAY($F8),1,0))/3)+1,INT(((YEAR(MIN((I$4+6),IF($G8="",(I$4+6),$G8)))-YEAR($F8))*12+MONTH(MIN((I$4+6),IF($G8="",(I$4+6),$G8)))-MONTH($F8)-IF(DAY(MIN((I$4+6),IF($G8="",(I$4+6),$G8)))<DAY($F8),1,0))/12)+1,1))-IF((I$4-1)<$F8,0,CHOOSE(MATCH($E8,{"Weekly","Every 2 weeks","Monthly","Quarterly","Yearly","One-time"},0),INT(((I$4-1)-$F8)/7)+1,INT(((I$4-1)-$F8)/14)+1,((YEAR((I$4-1))-YEAR($F8))*12+MONTH((I$4-1))-MONTH($F8)-IF(DAY((I$4-1))<DAY($F8),1,0))+1,INT(((YEAR((I$4-1))-YEAR($F8))*12+MONTH((I$4-1))-MONTH($F8)-IF(DAY((I$4-1))<DAY($F8),1,0))/3)+1,INT(((YEAR((I$4-1))-YEAR($F8))*12+MONTH((I$4-1))-MONTH($F8)-IF(DAY((I$4-1))<DAY($F8),1,0))/12)+1,1))),0)*$D8) -> 0 | J8: =IF(OR($A8="",$D8="",$E8="",$F8=""),0,IFERROR(MAX(0,IF(MIN((J$4+6),IF($G8="",(J$4+6),$G8))<$F8,0,CHOOSE(MATCH($E8,{"Weekly","Every 2 weeks","Monthly","Quarterly","Yearly","One-time"},0),INT((MIN((J$4+6),IF($G8="",(J$4+6),$G8))-$F8)/7)+1,INT((MIN((J$4+6),IF($G8="",(J$4+6),$G8))-$F8)/14)+1,((YEAR(MIN((J$4+6),IF($G8="",(J$4+6),$G8)))-YEAR($F8))*12+MONTH(MIN((J$4+6),IF($G8="",(J$4+6),$G8)))-MONTH($F8)-IF(DAY(MIN((J$4+6),IF($G8="",(J$4+6),$G8)))<DAY($F8),1,0))+1,INT(((YEAR(MIN((J$4+6),IF($G8="",(J$4+6),$G8)))-YEAR($F8))*12+MONTH(MIN((J$4+6),IF($G8="",(J$4+6),$G8)))-MONTH($F8)-IF(DAY(MIN((J$4+6),IF($G8="",(J$4+6),$G8)))<DAY($F8),1,0))/3)+1,INT(((YEAR(MIN((J$4+6),IF($G8="",(J$4+6),$G8)))-YEAR($F8))*12+MONTH(MIN((J$4+6),IF($G8="",(J$4+6),$G8)))-MONTH($F8)-IF(DAY(MIN((J$4+6),IF($G8="",(J$4+6),$G8)))<DAY($F8),1,0))/12)+1,1))-IF((J$4-1)<$F8,0,CHOOSE(MATCH($E8,{"Weekly","Every 2 weeks","Monthly","Quarterly","Yearly","One-time"},0),INT(((J$4-1)-$F8)/7)+1,INT(((J$4-1)-$F8)/14)+1,((YEAR((J$4-1))-YEAR($F8))*12+MONTH((J$4-1))-MONTH($F8)-IF(DAY((J$4-1))<DAY($F8),1,0))+1,INT(((YEAR((J$4-1))-YEAR($F8))*12+MONTH((J$4-1))-MONTH($F8)-IF(DAY((J$4-1))<DAY($F8),1,0))/3)+1,INT(((YEAR((J$4-1))-YEAR($F8))*12+MONTH((J$4-1))-MONTH($F8)-IF(DAY((J$4-1))<DAY($F8),1,0))/12)+1,1))),0)*$D8) -> 650 | K8: =IF(OR($A8="",$D8="",$E8="",$F8=""),0,IFERROR(MAX(0,IF(MIN((K$4+6),IF($G8="",(K$4+6),$G8))<$F8,0,CHOOSE(MATCH($E8,{"Weekly","Every 2 weeks","Monthly","Quarterly","Yearly","One-time"},0),INT((MIN((K$4+6),IF($G8="",(K$4+6),$G8))-$F8)/7)+1,INT((MIN((K$4+6),IF($G8="",(K$4+6),$G8))-$F8)/14)+1,((YEAR(MIN((K$4+6),IF($G8="",(K$4+6),$G8)))-YEAR($F8))*12+MONTH(MIN((K$4+6),IF($G8="",(K$4+6),$G8)))-MONTH($F8)-IF(DAY(MIN((K$4+6),IF($G8="",(K$4+6),$G8)))<DAY($F8),1,0))+1,INT(((YEAR(MIN((K$4+6),IF($G8="",(K$4+6),$G8)))-YEAR($F8))*12+MONTH(MIN((K$4+6),IF($G8="",(K$4+6),$G8)))-MONTH($F8)-IF(DAY(MIN((K$4+6),IF($G8="",(K$4+6),$G8)))<DAY($F8),1,0))/3)+1,INT(((YEAR(MIN((K$4+6),IF($G8="",(K$4+6),$G8)))-YEAR($F8))*12+MONTH(MIN((K$4+6),IF($G8="",(K$4+6),$G8)))-MONTH($F8)-IF(DAY(MIN((K$4+6),IF($G8="",(K$4+6),$G8)))<DAY($F8),1,0))/12)+1,1))-IF((K$4-1)<$F8,0,CHOOSE(MATCH($E8,{"Weekly","Every 2 weeks","Monthly","Quarterly","Yearly","One-time"},0),INT(((K$4-1)-$F8)/7)+1,INT(((K$4-1)-$F8)/14)+1,((YEAR((K$4-1))-YEAR($F8))*12+MONTH((K$4-1))-MONTH($F8)-IF(DAY((K$4-1))<DAY($F8),1,0))+1,INT(((YEAR((K$4-1))-YEAR($F8))*12+MONTH((K$4-1))-MONTH($F8)-IF(DAY((K$4-1))<DAY($F8),1,0))/3)+1,INT(((YEAR((K$4-1))-YEAR($F8))*12+MONTH((K$4-1))-MONTH($F8)-IF(DAY((K$4-1))<DAY($F8),1,0))/12)+1,1))),0)*$D8) -> 0 | L8: =IF(OR($A8="",$D8="",$E8="",$F8=""),0,IFERROR(MAX(0,IF(MIN((L$4+6),IF($G8="",(L$4+6),$G8))<$F8,0,CHOOSE(MATCH($E8,{"Weekly","Every 2 weeks","Monthly","Quarterly","Yearly","One-time"},0),INT((MIN((L$4+6),IF($G8="",(L$4+6),$G8))-$F8)/7)+1,INT((MIN((L$4+6),IF($G8="",(L$4+6),$G8))-$F8)/14)+1,((YEAR(MIN((L$4+6),IF($G8="",(L$4+6),$G8)))-YEAR($F8))*12+MONTH(MIN((L$4+6),IF($G8="",(L$4+6),$G8)))-MONTH($F8)-IF(DAY(MIN((L$4+6),IF($G8="",(L$4+6),$G8)))<DAY($F8),1,0))+1,INT(((YEAR(MIN((L$4+6),IF($G8="",(L$4+6),$G8)))-YEAR($F8))*12+MONTH(MIN((L$4+6),IF($G8="",(L$4+6),$G8)))-MONTH($F8)-IF(DAY(MIN((L$4+6),IF($G8="",(L$4+6),$G8)))<DAY($F8),1,0))/3)+1,INT(((YEAR(MIN((L$4+6),IF($G8="",(L$4+6),$G8)))-YEAR($F8))*12+MONTH(MIN((L$4+6),IF($G8="",(L$4+6),$G8)))-MONTH($F8)-IF(DAY(MIN((L$4+6),IF($G8="",(L$4+6),$G8)))<DAY($F8),1,0))/12)+1,1))-IF((L$4-1)<$F8,0,CHOOSE(MATCH($E8,{"Weekly","Every 2 weeks","Monthly","Quarterly","Yearly","One-time"},0),INT(((L$4-1)-$F8)/7)+1,INT(((L$4-1)-$F8)/14)+1,((YEAR((L$4-1))-YEAR($F8))*12+MONTH((L$4-1))-MONTH($F8)-IF(DAY((L$4-1))<DAY($F8),1,0))+1,INT(((YEAR((L$4-1))-YEAR($F8))*12+MONTH((L$4-1))-MONTH($F8)-IF(DAY((L$4-1))<DAY($F8),1,0))/3)+1,INT(((YEAR((L$4-1))-YEAR($F8))*12+MONTH((L$4-1))-MONTH($F8)-IF(DAY((L$4-1))<DAY($F8),1,0))/12)+1,1))),0)*$D8) -> 0
A9: Software subscriptions | B9: Software & Subscriptions | C9: Outflow | D9: 1150 | E9: Monthly | F9: 46331 | I9: =IF(OR($A9="",$D9="",$E9="",$F9=""),0,IFERROR(MAX(0,IF(MIN((I$4+6),IF($G9="",(I$4+6),$G9))<$F9,0,CHOOSE(MATCH($E9,{"Weekly","Every 2 weeks","Monthly","Quarterly","Yearly","One-time"},0),INT((MIN((I$4+6),IF($G9="",(I$4+6),$G9))-$F9)/7)+1,INT((MIN((I$4+6),IF($G9="",(I$4+6),$G9))-$F9)/14)+1,((YEAR(MIN((I$4+6),IF($G9="",(I$4+6),$G9)))-YEAR($F9))*12+MONTH(MIN((I$4+6),IF($G9="",(I$4+6),$G9)))-MONTH($F9)-IF(DAY(MIN((I$4+6),IF($G9="",(I$4+6),$G9)))<DAY($F9),1,0))+1,INT(((YEAR(MIN((I$4+6),IF($G9="",(I$4+6),$G9)))-YEAR($F9))*12+MONTH(MIN((I$4+6),IF($G9="",(I$4+6),$G9)))-MONTH($F9)-IF(DAY(MIN((I$4+6),IF($G9="",(I$4+6),$G9)))<DAY($F9),1,0))/3)+1,INT(((YEAR(MIN((I$4+6),IF($G9="",(I$4+6),$G9)))-YEAR($F9))*12+MONTH(MIN((I$4+6),IF($G9="",(I$4+6),$G9)))-MONTH($F9)-IF(DAY(MIN((I$4+6),IF($G9="",(I$4+6),$G9)))<DAY($F9),1,0))/12)+1,1))-IF((I$4-1)<$F9,0,CHOOSE(MATCH($E9,{"Weekly","Every 2 weeks","Monthly","Quarterly","Yearly","One-time"},0),INT(((I$4-1)-$F9)/7)+1,INT(((I$4-1)-$F9)/14)+1,((YEAR((I$4-1))-YEAR($F9))*12+MONTH((I$4-1))-MONTH($F9)-IF(DAY((I$4-1))<DAY($F9),1,0))+1,INT(((YEAR((I$4-1))-YEAR($F9))*12+MONTH((I$4-1))-MONTH($F9)-IF(DAY((I$4-1))<DAY($F9),1,0))/3)+1,INT(((YEAR((I$4-1))-YEAR($F9))*12+MONTH((I$4-1))-MONTH($F9)-IF(DAY((I$4-1))<DAY($F9),1,0))/12)+1,1))),0)*$D9) -> 1150 | J9: =IF(OR($A9="",$D9="",$E9="",$F9=""),0,IFERROR(MAX(0,IF(MIN((J$4+6),IF($G9="",(J$4+6),$G9))<$F9,0,CHOOSE(MATCH($E9,{"Weekly","Every 2 weeks","Monthly","Quarterly","Yearly","One-time"},0),INT((MIN((J$4+6),IF($G9="",(J$4+6),$G9))-$F9)/7)+1,INT((MIN((J$4+6),IF($G9="",(J$4+6),$G9))-$F9)/14)+1,((YEAR(MIN((J$4+6),IF($G9="",(J$4+6),$G9)))-YEAR($F9))*12+MONTH(MIN((J$4+6),IF($G9="",(J$4+6),$G9)))-MONTH($F9)-IF(DAY(MIN((J$4+6),IF($G9="",(J$4+6),$G9)))<DAY($F9),1,0))+1,INT(((YEAR(MIN((J$4+6),IF($G9="",(J$4+6),$G9)))-YEAR($F9))*12+MONTH(MIN((J$4+6),IF($G9="",(J$4+6),$G9)))-MONTH($F9)-IF(DAY(MIN((J$4+6),IF($G9="",(J$4+6),$G9)))<DAY($F9),1,0))/3)+1,INT(((YEAR(MIN((J$4+6),IF($G9="",(J$4+6),$G9)))-YEAR($F9))*12+MONTH(MIN((J$4+6),IF($G9="",(J$4+6),$G9)))-MONTH($F9)-IF(DAY(MIN((J$4+6),IF($G9="",(J$4+6),$G9)))<DAY($F9),1,0))/12)+1,1))-IF((J$4-1)<$F9,0,CHOOSE(MATCH($E9,{"Weekly","Every 2 weeks","Monthly","Quarterly","Yearly","One-time"},0),INT(((J$4-1)-$F9)/7)+1,INT(((J$4-1)-$F9)/14)+1,((YEAR((J$4-1))-YEAR($F9))*12+MONTH((J$4-1))-MONTH($F9)-IF(DAY((J$4-1))<DAY($F9),1,0))+1,INT(((YEAR((J$4-1))-YEAR($F9))*12+MONTH((J$4-1))-MONTH($F9)-IF(DAY((J$4-1))<DAY($F9),1,0))/3)+1,INT(((YEAR((J$4-1))-YEAR($F9))*12+MONTH((J$4-1))-MONTH($F9)-IF(DAY((J$4-1))<DAY($F9),1,0))/12)+1,1))),0)*$D9) -> 0 | K9: =IF(OR($A9="",$D9="",$E9="",$F9=""),0,IFERROR(MAX(0,IF(MIN((K$4+6),IF($G9="",(K$4+6),$G9))<$F9,0,CHOOSE(MATCH($E9,{"Weekly","Every 2 weeks","Monthly","Quarterly","Yearly","One-time"},0),INT((MIN((K$4+6),IF($G9="",(K$4+6),$G9))-$F9)/7)+1,INT((MIN((K$4+6),IF($G9="",(K$4+6),$G9))-$F9)/14)+1,((YEAR(MIN((K$4+6),IF($G9="",(K$4+6),$G9)))-YEAR($F9))*12+MONTH(MIN((K$4+6),IF($G9="",(K$4+6),$G9)))-MONTH($F9)-IF(DAY(MIN((K$4+6),IF($G9="",(K$4+6),$G9)))<DAY($F9),1,0))+1,INT(((YEAR(MIN((K$4+6),IF($G9="",(K$4+6),$G9)))-YEAR($F9))*12+MONTH(MIN((K$4+6),IF($G9="",(K$4+6),$G9)))-MONTH($F9)-IF(DAY(MIN((K$4+6),IF($G9="",(K$4+6),$G9)))<DAY($F9),1,0))/3)+1,INT(((YEAR(MIN((K$4+6),IF($G9="",(K$4+6),$G9)))-YEAR($F9))*12+MONTH(MIN((K$4+6),IF($G9="",(K$4+6),$G9)))-MONTH($F9)-IF(DAY(MIN((K$4+6),IF($G9="",(K$4+6),$G9)))<DAY($F9),1,0))/12)+1,1))-IF((K$4-1)<$F9,0,CHOOSE(MATCH($E9,{"Weekly","Every 2 weeks","Monthly","Quarterly","Yearly","One-time"},0),INT(((K$4-1)-$F9)/7)+1,INT(((K$4-1)-$F9)/14)+1,((YEAR((K$4-1))-YEAR($F9))*12+MONTH((K$4-1))-MONTH($F9)-IF(DAY((K$4-1))<DAY($F9),1,0))+1,INT(((YEAR((K$4-1))-YEAR($F9))*12+MONTH((K$4-1))-MONTH($F9)-IF(DAY((K$4-1))<DAY($F9),1,0))/3)+1,INT(((YEAR((K$4-1))-YEAR($F9))*12+MONTH((K$4-1))-MONTH($F9)-IF(DAY((K$4-1))<DAY($F9),1,0))/12)+1,1))),0)*$D9) -> 0 | L9: =IF(OR($A9="",$D9="",$E9="",$F9=""),0,IFERROR(MAX(0,IF(MIN((L$4+6),IF($G9="",(L$4+6),$G9))<$F9,0,CHOOSE(MATCH($E9,{"Weekly","Every 2 weeks","Monthly","Quarterly","Yearly","One-time"},0),INT((MIN((L$4+6),IF($G9="",(L$4+6),$G9))-$F9)/7)+1,INT((MIN((L$4+6),IF($G9="",(L$4+6),$G9))-$F9)/14)+1,((YEAR(MIN((L$4+6),IF($G9="",(L$4+6),$G9)))-YEAR($F9))*12+MONTH(MIN((L$4+6),IF($G9="",(L$4+6),$G9)))-MONTH($F9)-IF(DAY(MIN((L$4+6),IF($G9="",(L$4+6),$G9)))<DAY($F9),1,0))+1,INT(((YEAR(MIN((L$4+6),IF($G9="",(L$4+6),$G9)))-YEAR($F9))*12+MONTH(MIN((L$4+6),IF($G9="",(L$4+6),$G9)))-MONTH($F9)-IF(DAY(MIN((L$4+6),IF($G9="",(L$4+6),$G9)))<DAY($F9),1,0))/3)+1,INT(((YEAR(MIN((L$4+6),IF($G9="",(L$4+6),$G9)))-YEAR($F9))*12+MONTH(MIN((L$4+6),IF($G9="",(L$4+6),$G9)))-MONTH($F9)-IF(DAY(MIN((L$4+6),IF($G9="",(L$4+6),$G9)))<DAY($F9),1,0))/12)+1,1))-IF((L$4-1)<$F9,0,CHOOSE(MATCH($E9,{"Weekly","Every 2 weeks","Monthly","Quarterly","Yearly","One-time"},0),INT(((L$4-1)-$F9)/7)+1,INT(((L$4-1)-$F9)/14)+1,((YEAR((L$4-1))-YEAR($F9))*12+MONTH((L$4-1))-MONTH($F9)-IF(DAY((L$4-1))<DAY($F9),1,0))+1,INT(((YEAR((L$4-1))-YEAR($F9))*12+MONTH((L$4-1))-MONTH($F9)-IF(DAY((L$4-1))<DAY($F9),1,0))/3)+1,INT(((YEAR((L$4-1))-YEAR($F9))*12+MONTH((L$4-1))-MONTH($F9)-IF(DAY((L$4-1))<DAY($F9),1,0))/12)+1,1))),0)*$D9) -> 0
A10: Ads & marketing | B10: Marketing | C10: Outflow | D10: 2500 | E10: Monthly | F10: 46338 | I10: =IF(OR($A10="",$D10="",$E10="",$F10=""),0,IFERROR(MAX(0,IF(MIN((I$4+6),IF($G10="",(I$4+6),$G10))<$F10,0,CHOOSE(MATCH($E10,{"Weekly","Every 2 weeks","Monthly","Quarterly","Yearly","One-time"},0),INT((MIN((I$4+6),IF($G10="",(I$4+6),$G10))-$F10)/7)+1,INT((MIN((I$4+6),IF($G10="",(I$4+6),$G10))-$F10)/14)+1,((YEAR(MIN((I$4+6),IF($G10="",(I$4+6),$G10)))-YEAR($F10))*12+MONTH(MIN((I$4+6),IF($G10="",(I$4+6),$G10)))-MONTH($F10)-IF(DAY(MIN((I$4+6),IF($G10="",(I$4+6),$G10)))<DAY($F10),1,0))+1,INT(((YEAR(MIN((I$4+6),IF($G10="",(I$4+6),$G10)))-YEAR($F10))*12+MONTH(MIN((I$4+6),IF($G10="",(I$4+6),$G10)))-MONTH($F10)-IF(DAY(MIN((I$4+6),IF($G10="",(I$4+6),$G10)))<DAY($F10),1,0))/3)+1,INT(((YEAR(MIN((I$4+6),IF($G10="",(I$4+6),$G10)))-YEAR($F10))*12+MONTH(MIN((I$4+6),IF($G10="",(I$4+6),$G10)))-MONTH($F10)-IF(DAY(MIN((I$4+6),IF($G10="",(I$4+6),$G10)))<DAY($F10),1,0))/12)+1,1))-IF((I$4-1)<$F10,0,CHOOSE(MATCH($E10,{"Weekly","Every 2 weeks","Monthly","Quarterly","Yearly","One-time"},0),INT(((I$4-1)-$F10)/7)+1,INT(((I$4-1)-$F10)/14)+1,((YEAR((I$4-1))-YEAR($F10))*12+MONTH((I$4-1))-MONTH($F10)-IF(DAY((I$4-1))<DAY($F10),1,0))+1,INT(((YEAR((I$4-1))-YEAR($F10))*12+MONTH((I$4-1))-MONTH($F10)-IF(DAY((I$4-1))<DAY($F10),1,0))/3)+1,INT(((YEAR((I$4-1))-YEAR($F10))*12+MONTH((I$4-1))-MONTH($F10)-IF(DAY((I$4-1))<DAY($F10),1,0))/12)+1,1))),0)*$D10) -> 0 | J10: =IF(OR($A10="",$D10="",$E10="",$F10=""),0,IFERROR(MAX(0,IF(MIN((J$4+6),IF($G10="",(J$4+6),$G10))<$F10,0,CHOOSE(MATCH($E10,{"Weekly","Every 2 weeks","Monthly","Quarterly","Yearly","One-time"},0),INT((MIN((J$4+6),IF($G10="",(J$4+6),$G10))-$F10)/7)+1,INT((MIN((J$4+6),IF($G10="",(J$4+6),$G10))-$F10)/14)+1,((YEAR(MIN((J$4+6),IF($G10="",(J$4+6),$G10)))-YEAR($F10))*12+MONTH(MIN((J$4+6),IF($G10="",(J$4+6),$G10)))-MONTH($F10)-IF(DAY(MIN((J$4+6),IF($G10="",(J$4+6),$G10)))<DAY($F10),1,0))+1,INT(((YEAR(MIN((J$4+6),IF($G10="",(J$4+6),$G10)))-YEAR($F10))*12+MONTH(MIN((J$4+6),IF($G10="",(J$4+6),$G10)))-MONTH($F10)-IF(DAY(MIN((J$4+6),IF($G10="",(J$4+6),$G10)))<DAY($F10),1,0))/3)+1,INT(((YEAR(MIN((J$4+6),IF($G10="",(J$4+6),$G10)))-YEAR($F10))*12+MONTH(MIN((J$4+6),IF($G10="",(J$4+6),$G10)))-MONTH($F10)-IF(DAY(MIN((J$4+6),IF($G10="",(J$4+6),$G10)))<DAY($F10),1,0))/12)+1,1))-IF((J$4-1)<$F10,0,CHOOSE(MATCH($E10,{"Weekly","Every 2 weeks","Monthly","Quarterly","Yearly","One-time"},0),INT(((J$4-1)-$F10)/7)+1,INT(((J$4-1)-$F10)/14)+1,((YEAR((J$4-1))-YEAR($F10))*12+MONTH((J$4-1))-MONTH($F10)-IF(DAY((J$4-1))<DAY($F10),1,0))+1,INT(((YEAR((J$4-1))-YEAR($F10))*12+MONTH((J$4-1))-MONTH($F10)-IF(DAY((J$4-1))<DAY($F10),1,0))/3)+1,INT(((YEAR((J$4-1))-YEAR($F10))*12+MONTH((J$4-1))-MONTH($F10)-IF(DAY((J$4-1))<DAY($F10),1,0))/12)+1,1))),0)*$D10) -> 2500 | K10: =IF(OR($A10="",$D10="",$E10="",$F10=""),0,IFERROR(MAX(0,IF(MIN((K$4+6),IF($G10="",(K$4+6),$G10))<$F10,0,CHOOSE(MATCH($E10,{"Weekly","Every 2 weeks","Monthly","Quarterly","Yearly","One-time"},0),INT((MIN((K$4+6),IF($G10="",(K$4+6),$G10))-$F10)/7)+1,INT((MIN((K$4+6),IF($G10="",(K$4+6),$G10))-$F10)/14)+1,((YEAR(MIN((K$4+6),IF($G10="",(K$4+6),$G10)))-YEAR($F10))*12+MONTH(MIN((K$4+6),IF($G10="",(K$4+6),$G10)))-MONTH($F10)-IF(DAY(MIN((K$4+6),IF($G10="",(K$4+6),$G10)))<DAY($F10),1,0))+1,INT(((YEAR(MIN((K$4+6),IF($G10="",(K$4+6),$G10)))-YEAR($F10))*12+MONTH(MIN((K$4+6),IF($G10="",(K$4+6),$G10)))-MONTH($F10)-IF(DAY(MIN((K$4+6),IF($G10="",(K$4+6),$G10)))<DAY($F10),1,0))/3)+1,INT(((YEAR(MIN((K$4+6),IF($G10="",(K$4+6),$G10)))-YEAR($F10))*12+MONTH(MIN((K$4+6),IF($G10="",(K$4+6),$G10)))-MONTH($F10)-IF(DAY(MIN((K$4+6),IF($G10="",(K$4+6),$G10)))<DAY($F10),1,0))/12)+1,1))-IF((K$4-1)<$F10,0,CHOOSE(MATCH($E10,{"Weekly","Every 2 weeks","Monthly","Quarterly","Yearly","One-time"},0),INT(((K$4-1)-$F10)/7)+1,INT(((K$4-1)-$F10)/14)+1,((YEAR((K$4-1))-YEAR($F10))*12+MONTH((K$4-1))-MONTH($F10)-IF(DAY((K$4-1))<DAY($F10),1,0))+1,INT(((YEAR((K$4-1))-YEAR($F10))*12+MONTH((K$4-1))-MONTH($F10)-IF(DAY((K$4-1))<DAY($F10),1,0))/3)+1,INT(((YEAR((K$4-1))-YEAR($F10))*12+MONTH((K$4-1))-MONTH($F10)-IF(DAY((K$4-1))<DAY($F10),1,0))/12)+1,1))),0)*$D10) -> 0 | L10: =IF(OR($A10="",$D10="",$E10="",$F10=""),0,IFERROR(MAX(0,IF(MIN((L$4+6),IF($G10="",(L$4+6),$G10))<$F10,0,CHOOSE(MATCH($E10,{"Weekly","Every 2 weeks","Monthly","Quarterly","Yearly","One-time"},0),INT((MIN((L$4+6),IF($G10="",(L$4+6),$G10))-$F10)/7)+1,INT((MIN((L$4+6),IF($G10="",(L$4+6),$G10))-$F10)/14)+1,((YEAR(MIN((L$4+6),IF($G10="",(L$4+6),$G10)))-YEAR($F10))*12+MONTH(MIN((L$4+6),IF($G10="",(L$4+6),$G10)))-MONTH($F10)-IF(DAY(MIN((L$4+6),IF($G10="",(L$4+6),$G10)))<DAY($F10),1,0))+1,INT(((YEAR(MIN((L$4+6),IF($G10="",(L$4+6),$G10)))-YEAR($F10))*12+MONTH(MIN((L$4+6),IF($G10="",(L$4+6),$G10)))-MONTH($F10)-IF(DAY(MIN((L$4+6),IF($G10="",(L$4+6),$G10)))<DAY($F10),1,0))/3)+1,INT(((YEAR(MIN((L$4+6),IF($G10="",(L$4+6),$G10)))-YEAR($F10))*12+MONTH(MIN((L$4+6),IF($G10="",(L$4+6),$G10)))-MONTH($F10)-IF(DAY(MIN((L$4+6),IF($G10="",(L$4+6),$G10)))<DAY($F10),1,0))/12)+1,1))-IF((L$4-1)<$F10,0,CHOOSE(MATCH($E10,{"Weekly","Every 2 weeks","Monthly","Quarterly","Yearly","One-time"},0),INT(((L$4-1)-$F10)/7)+1,INT(((L$4-1)-$F10)/14)+1,((YEAR((L$4-1))-YEAR($F10))*12+MONTH((L$4-1))-MONTH($F10)-IF(DAY((L$4-1))<DAY($F10),1,0))+1,INT(((YEAR((L$4-1))-YEAR($F10))*12+MONTH((L$4-1))-MONTH($F10)-IF(DAY((L$4-1))<DAY($F10),1,0))/3)+1,INT(((YEAR((L$4-1))-YEAR($F10))*12+MONTH((L$4-1))-MONTH($F10)-IF(DAY((L$4-1))<DAY($F10),1,0))/12)+1,1))),0)*$D10) -> 0
A11: Equipment loan | B11: Loan Payments | C11: Outflow | D11: 1380 | E11: Monthly | F11: 46346 | I11: =IF(OR($A11="",$D11="",$E11="",$F11=""),0,IFERROR(MAX(0,IF(MIN((I$4+6),IF($G11="",(I$4+6),$G11))<$F11,0,CHOOSE(MATCH($E11,{"Weekly","Every 2 weeks","Monthly","Quarterly","Yearly","One-time"},0),INT((MIN((I$4+6),IF($G11="",(I$4+6),$G11))-$F11)/7)+1,INT((MIN((I$4+6),IF($G11="",(I$4+6),$G11))-$F11)/14)+1,((YEAR(MIN((I$4+6),IF($G11="",(I$4+6),$G11)))-YEAR($F11))*12+MONTH(MIN((I$4+6),IF($G11="",(I$4+6),$G11)))-MONTH($F11)-IF(DAY(MIN((I$4+6),IF($G11="",(I$4+6),$G11)))<DAY($F11),1,0))+1,INT(((YEAR(MIN((I$4+6),IF($G11="",(I$4+6),$G11)))-YEAR($F11))*12+MONTH(MIN((I$4+6),IF($G11="",(I$4+6),$G11)))-MONTH($F11)-IF(DAY(MIN((I$4+6),IF($G11="",(I$4+6),$G11)))<DAY($F11),1,0))/3)+1,INT(((YEAR(MIN((I$4+6),IF($G11="",(I$4+6),$G11)))-YEAR($F11))*12+MONTH(MIN((I$4+6),IF($G11="",(I$4+6),$G11)))-MONTH($F11)-IF(DAY(MIN((I$4+6),IF($G11="",(I$4+6),$G11)))<DAY($F11),1,0))/12)+1,1))-IF((I$4-1)<$F11,0,CHOOSE(MATCH($E11,{"Weekly","Every 2 weeks","Monthly","Quarterly","Yearly","One-time"},0),INT(((I$4-1)-$F11)/7)+1,INT(((I$4-1)-$F11)/14)+1,((YEAR((I$4-1))-YEAR($F11))*12+MONTH((I$4-1))-MONTH($F11)-IF(DAY((I$4-1))<DAY($F11),1,0))+1,INT(((YEAR((I$4-1))-YEAR($F11))*12+MONTH((I$4-1))-MONTH($F11)-IF(DAY((I$4-1))<DAY($F11),1,0))/3)+1,INT(((YEAR((I$4-1))-YEAR($F11))*12+MONTH((I$4-1))-MONTH($F11)-IF(DAY((I$4-1))<DAY($F11),1,0))/12)+1,1))),0)*$D11) -> 0 | J11: =IF(OR($A11="",$D11="",$E11="",$F11=""),0,IFERROR(MAX(0,IF(MIN((J$4+6),IF($G11="",(J$4+6),$G11))<$F11,0,CHOOSE(MATCH($E11,{"Weekly","Every 2 weeks","Monthly","Quarterly","Yearly","One-time"},0),INT((MIN((J$4+6),IF($G11="",(J$4+6),$G11))-$F11)/7)+1,INT((MIN((J$4+6),IF($G11="",(J$4+6),$G11))-$F11)/14)+1,((YEAR(MIN((J$4+6),IF($G11="",(J$4+6),$G11)))-YEAR($F11))*12+MONTH(MIN((J$4+6),IF($G11="",(J$4+6),$G11)))-MONTH($F11)-IF(DAY(MIN((J$4+6),IF($G11="",(J$4+6),$G11)))<DAY($F11),1,0))+1,INT(((YEAR(MIN((J$4+6),IF($G11="",(J$4+6),$G11)))-YEAR($F11))*12+MONTH(MIN((J$4+6),IF($G11="",(J$4+6),$G11)))-MONTH($F11)-IF(DAY(MIN((J$4+6),IF($G11="",(J$4+6),$G11)))<DAY($F11),1,0))/3)+1,INT(((YEAR(MIN((J$4+6),IF($G11="",(J$4+6),$G11)))-YEAR($F11))*12+MONTH(MIN((J$4+6),IF($G11="",(J$4+6),$G11)))-MONTH($F11)-IF(DAY(MIN((J$4+6),IF($G11="",(J$4+6),$G11)))<DAY($F11),1,0))/12)+1,1))-IF((J$4-1)<$F11,0,CHOOSE(MATCH($E11,{"Weekly","Every 2 weeks","Monthly","Quarterly","Yearly","One-time"},0),INT(((J$4-1)-$F11)/7)+1,INT(((J$4-1)-$F11)/14)+1,((YEAR((J$4-1))-YEAR($F11))*12+MONTH((J$4-1))-MONTH($F11)-IF(DAY((J$4-1))<DAY($F11),1,0))+1,INT(((YEAR((J$4-1))-YEAR($F11))*12+MONTH((J$4-1))-MONTH($F11)-IF(DAY((J$4-1))<DAY($F11),1,0))/3)+1,INT(((YEAR((J$4-1))-YEAR($F11))*12+MONTH((J$4-1))-MONTH($F11)-IF(DAY((J$4-1))<DAY($F11),1,0))/12)+1,1))),0)*$D11) -> 0 | K11: =IF(OR($A11="",$D11="",$E11="",$F11=""),0,IFERROR(MAX(0,IF(MIN((K$4+6),IF($G11="",(K$4+6),$G11))<$F11,0,CHOOSE(MATCH($E11,{"Weekly","Every 2 weeks","Monthly","Quarterly","Yearly","One-time"},0),INT((MIN((K$4+6),IF($G11="",(K$4+6),$G11))-$F11)/7)+1,INT((MIN((K$4+6),IF($G11="",(K$4+6),$G11))-$F11)/14)+1,((YEAR(MIN((K$4+6),IF($G11="",(K$4+6),$G11)))-YEAR($F11))*12+MONTH(MIN((K$4+6),IF($G11="",(K$4+6),$G11)))-MONTH($F11)-IF(DAY(MIN((K$4+6),IF($G11="",(K$4+6),$G11)))<DAY($F11),1,0))+1,INT(((YEAR(MIN((K$4+6),IF($G11="",(K$4+6),$G11)))-YEAR($F11))*12+MONTH(MIN((K$4+6),IF($G11="",(K$4+6),$G11)))-MONTH($F11)-IF(DAY(MIN((K$4+6),IF($G11="",(K$4+6),$G11)))<DAY($F11),1,0))/3)+1,INT(((YEAR(MIN((K$4+6),IF($G11="",(K$4+6),$G11)))-YEAR($F11))*12+MONTH(MIN((K$4+6),IF($G11="",(K$4+6),$G11)))-MONTH($F11)-IF(DAY(MIN((K$4+6),IF($G11="",(K$4+6),$G11)))<DAY($F11),1,0))/12)+1,1))-IF((K$4-1)<$F11,0,CHOOSE(MATCH($E11,{"Weekly","Every 2 weeks","Monthly","Quarterly","Yearly","One-time"},0),INT(((K$4-1)-$F11)/7)+1,INT(((K$4-1)-$F11)/14)+1,((YEAR((K$4-1))-YEAR($F11))*12+MONTH((K$4-1))-MONTH($F11)-IF(DAY((K$4-1))<DAY($F11),1,0))+1,INT(((YEAR((K$4-1))-YEAR($F11))*12+MONTH((K$4-1))-MONTH($F11)-IF(DAY((K$4-1))<DAY($F11),1,0))/3)+1,INT(((YEAR((K$4-1))-YEAR($F11))*12+MONTH((K$4-1))-MONTH($F11)-IF(DAY((K$4-1))<DAY($F11),1,0))/12)+1,1))),0)*$D11) -> 1380 | L11: =IF(OR($A11="",$D11="",$E11="",$F11=""),0,IFERROR(MAX(0,IF(MIN((L$4+6),IF($G11="",(L$4+6),$G11))<$F11,0,CHOOSE(MATCH($E11,{"Weekly","Every 2 weeks","Monthly","Quarterly","Yearly","One-time"},0),INT((MIN((L$4+6),IF($G11="",(L$4+6),$G11))-$F11)/7)+1,INT((MIN((L$4+6),IF($G11="",(L$4+6),$G11))-$F11)/14)+1,((YEAR(MIN((L$4+6),IF($G11="",(L$4+6),$G11)))-YEAR($F11))*12+MONTH(MIN((L$4+6),IF($G11="",(L$4+6),$G11)))-MONTH($F11)-IF(DAY(MIN((L$4+6),IF($G11="",(L$4+6),$G11)))<DAY($F11),1,0))+1,INT(((YEAR(MIN((L$4+6),IF($G11="",(L$4+6),$G11)))-YEAR($F11))*12+MONTH(MIN((L$4+6),IF($G11="",(L$4+6),$G11)))-MONTH($F11)-IF(DAY(MIN((L$4+6),IF($G11="",(L$4+6),$G11)))<DAY($F11),1,0))/3)+1,INT(((YEAR(MIN((L$4+6),IF($G11="",(L$4+6),$G11)))-YEAR($F11))*12+MONTH(MIN((L$4+6),IF($G11="",(L$4+6),$G11)))-MONTH($F11)-IF(DAY(MIN((L$4+6),IF($G11="",(L$4+6),$G11)))<DAY($F11),1,0))/12)+1,1))-IF((L$4-1)<$F11,0,CHOOSE(MATCH($E11,{"Weekly","Every 2 weeks","Monthly","Quarterly","Yearly","One-time"},0),INT(((L$4-1)-$F11)/7)+1,INT(((L$4-1)-$F11)/14)+1,((YEAR((L$4-1))-YEAR($F11))*12+MONTH((L$4-1))-MONTH($F11)-IF(DAY((L$4-1))<DAY($F11),1,0))+1,INT(((YEAR((L$4-1))-YEAR($F11))*12+MONTH((L$4-1))-MONTH($F11)-IF(DAY((L$4-1))<DAY($F11),1,0))/3)+1,INT(((YEAR((L$4-1))-YEAR($F11))*12+MONTH((L$4-1))-MONTH($F11)-IF(DAY((L$4-1))<DAY($F11),1,0))/12)+1,1))),0)*$D11) -> 0
A12: Estimated tax | B12: Taxes | C12: Outflow | D12: 9000 | E12: Quarterly | F12: 46371 | I12: =IF(OR($A12="",$D12="",$E12="",$F12=""),0,IFERROR(MAX(0,IF(MIN((I$4+6),IF($G12="",(I$4+6),$G12))<$F12,0,CHOOSE(MATCH($E12,{"Weekly","Every 2 weeks","Monthly","Quarterly","Yearly","One-time"},0),INT((MIN((I$4+6),IF($G12="",(I$4+6),$G12))-$F12)/7)+1,INT((MIN((I$4+6),IF($G12="",(I$4+6),$G12))-$F12)/14)+1,((YEAR(MIN((I$4+6),IF($G12="",(I$4+6),$G12)))-YEAR($F12))*12+MONTH(MIN((I$4+6),IF($G12="",(I$4+6),$G12)))-MONTH($F12)-IF(DAY(MIN((I$4+6),IF($G12="",(I$4+6),$G12)))<DAY($F12),1,0))+1,INT(((YEAR(MIN((I$4+6),IF($G12="",(I$4+6),$G12)))-YEAR($F12))*12+MONTH(MIN((I$4+6),IF($G12="",(I$4+6),$G12)))-MONTH($F12)-IF(DAY(MIN((I$4+6),IF($G12="",(I$4+6),$G12)))<DAY($F12),1,0))/3)+1,INT(((YEAR(MIN((I$4+6),IF($G12="",(I$4+6),$G12)))-YEAR($F12))*12+MONTH(MIN((I$4+6),IF($G12="",(I$4+6),$G12)))-MONTH($F12)-IF(DAY(MIN((I$4+6),IF($G12="",(I$4+6),$G12)))<DAY($F12),1,0))/12)+1,1))-IF((I$4-1)<$F12,0,CHOOSE(MATCH($E12,{"Weekly","Every 2 weeks","Monthly","Quarterly","Yearly","One-time"},0),INT(((I$4-1)-$F12)/7)+1,INT(((I$4-1)-$F12)/14)+1,((YEAR((I$4-1))-YEAR($F12))*12+MONTH((I$4-1))-MONTH($F12)-IF(DAY((I$4-1))<DAY($F12),1,0))+1,INT(((YEAR((I$4-1))-YEAR($F12))*12+MONTH((I$4-1))-MONTH($F12)-IF(DAY((I$4-1))<DAY($F12),1,0))/3)+1,INT(((YEAR((I$4-1))-YEAR($F12))*12+MONTH((I$4-1))-MONTH($F12)-IF(DAY((I$4-1))<DAY($F12),1,0))/12)+1,1))),0)*$D12) -> 0 | J12: =IF(OR($A12="",$D12="",$E12="",$F12=""),0,IFERROR(MAX(0,IF(MIN((J$4+6),IF($G12="",(J$4+6),$G12))<$F12,0,CHOOSE(MATCH($E12,{"Weekly","Every 2 weeks","Monthly","Quarterly","Yearly","One-time"},0),INT((MIN((J$4+6),IF($G12="",(J$4+6),$G12))-$F12)/7)+1,INT((MIN((J$4+6),IF($G12="",(J$4+6),$G12))-$F12)/14)+1,((YEAR(MIN((J$4+6),IF($G12="",(J$4+6),$G12)))-YEAR($F12))*12+MONTH(MIN((J$4+6),IF($G12="",(J$4+6),$G12)))-MONTH($F12)-IF(DAY(MIN((J$4+6),IF($G12="",(J$4+6),$G12)))<DAY($F12),1,0))+1,INT(((YEAR(MIN((J$4+6),IF($G12="",(J$4+6),$G12)))-YEAR($F12))*12+MONTH(MIN((J$4+6),IF($G12="",(J$4+6),$G12)))-MONTH($F12)-IF(DAY(MIN((J$4+6),IF($G12="",(J$4+6),$G12)))<DAY($F12),1,0))/3)+1,INT(((YEAR(MIN((J$4+6),IF($G12="",(J$4+6),$G12)))-YEAR($F12))*12+MONTH(MIN((J$4+6),IF($G12="",(J$4+6),$G12)))-MONTH($F12)-IF(DAY(MIN((J$4+6),IF($G12="",(J$4+6),$G12)))<DAY($F12),1,0))/12)+1,1))-IF((J$4-1)<$F12,0,CHOOSE(MATCH($E12,{"Weekly","Every 2 weeks","Monthly","Quarterly","Yearly","One-time"},0),INT(((J$4-1)-$F12)/7)+1,INT(((J$4-1)-$F12)/14)+1,((YEAR((J$4-1))-YEAR($F12))*12+MONTH((J$4-1))-MONTH($F12)-IF(DAY((J$4-1))<DAY($F12),1,0))+1,INT(((YEAR((J$4-1))-YEAR($F12))*12+MONTH((J$4-1))-MONTH($F12)-IF(DAY((J$4-1))<DAY($F12),1,0))/3)+1,INT(((YEAR((J$4-1))-YEAR($F12))*12+MONTH((J$4-1))-MONTH($F12)-IF(DAY((J$4-1))<DAY($F12),1,0))/12)+1,1))),0)*$D12) -> 0 | K12: =IF(OR($A12="",$D12="",$E12="",$F12=""),0,IFERROR(MAX(0,IF(MIN((K$4+6),IF($G12="",(K$4+6),$G12))<$F12,0,CHOOSE(MATCH($E12,{"Weekly","Every 2 weeks","Monthly","Quarterly","Yearly","One-time"},0),INT((MIN((K$4+6),IF($G12="",(K$4+6),$G12))-$F12)/7)+1,INT((MIN((K$4+6),IF($G12="",(K$4+6),$G12))-$F12)/14)+1,((YEAR(MIN((K$4+6),IF($G12="",(K$4+6),$G12)))-YEAR($F12))*12+MONTH(MIN((K$4+6),IF($G12="",(K$4+6),$G12)))-MONTH($F12)-IF(DAY(MIN((K$4+6),IF($G12="",(K$4+6),$G12)))<DAY($F12),1,0))+1,INT(((YEAR(MIN((K$4+6),IF($G12="",(K$4+6),$G12)))-YEAR($F12))*12+MONTH(MIN((K$4+6),IF($G12="",(K$4+6),$G12)))-MONTH($F12)-IF(DAY(MIN((K$4+6),IF($G12="",(K$4+6),$G12)))<DAY($F12),1,0))/3)+1,INT(((YEAR(MIN((K$4+6),IF($G12="",(K$4+6),$G12)))-YEAR($F12))*12+MONTH(MIN((K$4+6),IF($G12="",(K$4+6),$G12)))-MONTH($F12)-IF(DAY(MIN((K$4+6),IF($G12="",(K$4+6),$G12)))<DAY($F12),1,0))/12)+1,1))-IF((K$4-1)<$F12,0,CHOOSE(MATCH($E12,{"Weekly","Every 2 weeks","Monthly","Quarterly","Yearly","One-time"},0),INT(((K$4-1)-$F12)/7)+1,INT(((K$4-1)-$F12)/14)+1,((YEAR((K$4-1))-YEAR($F12))*12+MONTH((K$4-1))-MONTH($F12)-IF(DAY((K$4-1))<DAY($F12),1,0))+1,INT(((YEAR((K$4-1))-YEAR($F12))*12+MONTH((K$4-1))-MONTH($F12)-IF(DAY((K$4-1))<DAY($F12),1,0))/3)+1,INT(((YEAR((K$4-1))-YEAR($F12))*12+MONTH((K$4-1))-MONTH($F12)-IF(DAY((K$4-1))<DAY($F12),1,0))/12)+1,1))),0)*$D12) -> 0 | L12: =IF(OR($A12="",$D12="",$E12="",$F12=""),0,IFERROR(MAX(0,IF(MIN((L$4+6),IF($G12="",(L$4+6),$G12))<$F12,0,CHOOSE(MATCH($E12,{"Weekly","Every 2 weeks","Monthly","Quarterly","Yearly","One-time"},0),INT((MIN((L$4+6),IF($G12="",(L$4+6),$G12))-$F12)/7)+1,INT((MIN((L$4+6),IF($G12="",(L$4+6),$G12))-$F12)/14)+1,((YEAR(MIN((L$4+6),IF($G12="",(L$4+6),$G12)))-YEAR($F12))*12+MONTH(MIN((L$4+6),IF($G12="",(L$4+6),$G12)))-MONTH($F12)-IF(DAY(MIN((L$4+6),IF($G12="",(L$4+6),$G12)))<DAY($F12),1,0))+1,INT(((YEAR(MIN((L$4+6),IF($G12="",(L$4+6),$G12)))-YEAR($F12))*12+MONTH(MIN((L$4+6),IF($G12="",(L$4+6),$G12)))-MONTH($F12)-IF(DAY(MIN((L$4+6),IF($G12="",(L$4+6),$G12)))<DAY($F12),1,0))/3)+1,INT(((YEAR(MIN((L$4+6),IF($G12="",(L$4+6),$G12)))-YEAR($F12))*12+MONTH(MIN((L$4+6),IF($G12="",(L$4+6),$G12)))-MONTH($F12)-IF(DAY(MIN((L$4+6),IF($G12="",(L$4+6),$G12)))<DAY($F12),1,0))/12)+1,1))-IF((L$4-1)<$F12,0,CHOOSE(MATCH($E12,{"Weekly","Every 2 weeks","Monthly","Quarterly","Yearly","One-time"},0),INT(((L$4-1)-$F12)/7)+1,INT(((L$4-1)-$F12)/14)+1,((YEAR((L$4-1))-YEAR($F12))*12+MONTH((L$4-1))-MONTH($F12)-IF(DAY((L$4-1))<DAY($F12),1,0))+1,INT(((YEAR((L$4-1))-YEAR($F12))*12+MONTH((L$4-1))-MONTH($F12)-IF(DAY((L$4-1))<DAY($F12),1,0))/3)+1,INT(((YEAR((L$4-1))-YEAR($F12))*12+MONTH((L$4-1))-MONTH($F12)-IF(DAY((L$4-1))<DAY($F12),1,0))/12)+1,1))),0)*$D12) -> 0
